Workbook

Sheet README
A1: US State IVF Access Dataset (2026 snapshot)
A3: Version | B3: v1.0
A4: Release date | B4: 2026-03-12
A5: Contents | B5: data, codebook, index_logic, methodology
A7: How to cite
A8: Suggested citation | B8: US State IVF Access Dataset (2026 snapshot), compiled by user with structured coding support from OpenAI ChatGPT.
A10: State IVF Access Index
A11: Scale | B11: 0-100
A12: Interpretation | B12: Higher scores indicate stronger insurance access, more inclusive eligibility, fewer embryo/personhood constraints, and greater clinic/utilization access.
A14: Key sources
A15: https://triagecancer.org/state-laws/health-insurance-fertility-services
A16: https://www.reproductivefacts.org/patient-advocacy/state-and-territory-infertility-insurance-laws/
A17: https://surrogacy360.org/wp-content/uploads/2024/08/Regulation-Details-in-the-US-by-State_8.6.24.pdf
A18: https://www.cdc.gov/art/php/surveillance-state-specific/index.html
A19: https://www.cms.gov/marketplace/in-person-assisters/training-webinars/training/marketplaces-map
A20: https://ballotpedia.org/State_government_trifectas
A21: https://www.guttmacher.org/united-states/abortion

Sheet data
A1: state | B1: state_abbrev | C1: year | D1: policy_status | E1: policy_start_year | F1: policy_end_year | G1: policy_last_updated | H1: insurance_mandate | I1: mandate_scope | J1: coverage_type | K1: cycle_limit | L1: lifetime_limit | M1: financial_cap | N1: medication_coverage | O1: fertility_preservation_coverage | P1: donor_gamete_coverage | Q1: embryo_transfer_limit | R1: religious_exemption | S1: medicaid_ivf_coverage | T1: medicaid_infertility_services | U1: state_subsidy_program | V1: public_funding_amount | W1: state_employee_ivf_coverage | X1: marital_requirement | Y1: infertility_definition | Z1: prior_treatment_requirement | AA1: age_limit_female | AB1: age_limit_male | AC1: residency_requirement | AD1: lgbtq_access | AE1: single_parent_access | AF1: gender_identity_access | AG1: donor_requirement_rules | AH1: embryo_personhood_law | AI1: embryo_storage_regulation | AJ1: embryo_disposition_rules | AK1: embryo_research_restrictions | AL1: fetal_personhood_related_laws | AM1: surrogacy_status | AN1: commercial_surrogacy_allowed | AO1: surrogacy_contract_enforceable | AP1: gestational_surrogacy_only | AQ1: parentage_rules | AR1: clinic_licensing_requirement | AS1: state_reporting_requirements | AT1: success_rate_reporting | AU1: lab_regulation | AV1: mandate_year_enacted | AW1: mandate_last_revised | AX1: major_policy_change | AY1: policy_strength_score | AZ1: ivf_clinics_count | BA1: ivf_cycles_per_year | BB1: population | BC1: insurance_market_type | BD1: political_control | BE1: abortion_policy_index | BF1: policy_source | BG1: statute_link | BH1: secondary_source | BI1: coding_notes | BJ1: coder_initials | BK1: verification_status | BL1: clinic_density_per_million | BM1: cycle_rate_per_million | BN1: subscore_insurance | BO1: subscore_equity | BP1: subscore_surrogacy | BQ1: subscore_embryo_regulation | BR1: subscore_repro_policy_env | BS1: subscore_clinic_density | BT1: subscore_cycle_rate | BU1: ivf_access_index | BV1: ivf_access_tier
A2: Alabama | B2: AL | C2: 2026 | D2: current_snapshot | E2: 0 | F2: NA | G2: 2026-03-12 | H2: none_identified | I2: No statewide infertility/IVF coverage mandate identified in source used | J2: no_statewide_ivf_mandate_identified | K2: 0 | L2: 0 | M2: 0 | N2: 0 | O2: not identified | P2: 0 | Q2: 0 | R2: 0 | U2: none_identified | V2: 0 | X2: no_statewide_ivf_treatment_eligibility_rule_identified | Y2: no_statewide_ivf_treatment_eligibility_rule_identified | Z2: no_statewide_ivf_treatment_eligibility_rule_identified | AA2: not_applicable_no_statewide_ivf_treatment_mandate | AB2: not_applicable_no_statewide_ivf_treatment_mandate | AC2: none stated in source used | AD2: no_statewide_ivf_treatment_eligibility_rule_identified | AE2: no_statewide_ivf_treatment_eligibility_rule_identified | AF2: no_statewide_ivf_treatment_eligibility_rule_identified | AG2: no_statewide_ivf_treatment_eligibility_rule_identified | AH2: yes_court_ruling_frozen_embryos_children | AI2: legal_uncertainty_after_2024_ruling | AJ2: legal_uncertainty_after_2024_ruling; 2024 immunity law for IVF providers does not resolve embryo status | AK2: not identified in secondary sources used | AL2: 2018 constitutional amendment on rights of unborn children cited in 2024 ruling | AM2: restricted | AN2: yes | AO2: no_or_unclear | AP2: unclear | AQ2: adoption or post-birth process often required | AR2: no_fertility_specific_state_clinic_license_coded_in_this_pass | AS2: federal_CDC_NASS_reporting_baseline | AT2: federal_FCSRCA_CDC_public_reporting | AU2: CLIA_CMS_FDA_baseline; state_variation_not_fully_coded | AV2: 0 | AW2: 0 | AX2: 0 | AY2: =BU2 -> 12 | AZ2: 5 | BA2: 1694 | BB2: 5157699 | BC2: FFM | BD2: republican_trifecta | BE2: near_total_ban_or_total_ban_environment | BF2: No statewide infertility/IVF mandate identified in Triage Cancer state-law chart | BG2: https://triagecancer.org/state-laws/health-insurance-fertility-services | BH2: https://triagecancer.org/state-laws/health-insurance-fertility-services; https://surrogacy360.org/wp-content/uploads/2024/08/Regulation-Details-in-the-US-by-State_8.6.24.pdf; https://www.reuters.com/business/healthcare-pharmaceuticals/alabamas-highest-court-ruled-frozen-embryos-are-people-what-is-next-2024-02-23/; https://www.asrm.org/advocacy-and-policy/reproductive-rights/summary-reports/state-abortion-laws-potential-implications-for-reproductive-medicine/; https://www.guttmacher.org/2025/12/state-policy-trends-2025-full-year-analysis; https://www.reuters.com/world/us/republican-alabama-governor-signs-ivf-protections-into-law-2024-03-07/; https://www.cdc.gov/art/php/nass/index.html; https://www.cdc.gov/art/success-rates/index.html; https://www.cms.gov/medicare/quality/clinical-laboratory-improvement-amendments; https://www.cms.gov/marketplace/in-person-assisters/training-webinars/training/marketplaces-map; https://ballotpedia.org/State_government_trifectas; https://www.britannica.com/topic/largest-U-S-state-by-population; https://www.guttmacher.org/united-states/abortion | BI2: Starter row only. Needs primary-law verification for Medicaid, public funding, eligibility, embryo rules, surrogacy, clinic regulation, and utilization variables. Surrogacy fields coded from Surrogacy360 2024 state-by-state summary; interpret as starter classification requiring legal review for publication. Eligibility/LGBTQ fields on this row were filled as a 2026 starter classification based on absence of a statewide IVF-treatment mandate or unclear scope in the source used; this should not be interpreted as a full review of all private plans or clinic access in the state. Embryo/personhood/disposition fields were filled conservatively in this pass. Unless a state had a clear embryo-specific rule in the secondary sources used, values were set to not_identified_in_secondary_sources_used rather than treated as definitive absence of law. Clinic/reporting fields in this pass were coded from federal baselines: CDC NASS/FCSRCA reporting and CMS CLIA materials; insurance marketplace type from CMS Plan Year 2026 marketplace map; political control from Ballotpedia current trifecta status; population uses 2024 state estimate table summarized by Britannica from U.S. Census data. IVF clinic counts and cycle counts remain blank pending direct state-level CDC extraction. | BJ2: RRM | BK2: partially_filled_needs_primary_law_review | BL2: =IFERROR((AZ2/BB2)*1000000,0) -> 0.96942454 | BM2: =IFERROR((BA2/BB2)*1000000,0) -> 328.44104 | BN2: =IFERROR(VLOOKUP(H2,index_logic!$A$4:$B$8,2,FALSE),0) -> 0 | BO2: =IFERROR(VLOOKUP(AD2,index_logic!$D$4:$E$21,2,FALSE),0) -> 3 | BP2: =IFERROR(VLOOKUP(AM2,index_logic!$G$4:$H$6,2,FALSE),0) -> 3 | BQ2: =IFERROR(VLOOKUP(AH2,index_logic!$J$4:$K$6,2,FALSE),0) -> 0 | BR2: =IFERROR(VLOOKUP(BE2,index_logic!$M$4:$N$7,2,FALSE),0) -> 0 | BS2: =IFERROR(VLOOKUP(BL2,index_logic!$P$4:$Q$9,2,TRUE),0) -> 4 | BT2: =IFERROR(VLOOKUP(BM2,index_logic!$S$4:$T$9,2,TRUE),0) -> 2 | BU2: =BN2+BO2+BP2+BQ2+BR2+BS2+BT2 -> 12 | BV2: =IF(BU2>=80,"Very High",IF(BU2>=65,"High",IF(BU2>=50,"Moderate",IF(BU2>=35,"Low","Very Low")))) -> Very Low
A3: Alaska | B3: AK | C3: 2026 | D3: current_snapshot | E3: 0 | F3: NA | G3: 2026-03-12 | H3: none_identified | I3: No statewide infertility/IVF coverage mandate identified in source used | J3: no_statewide_ivf_mandate_identified | K3: 0 | L3: 0 | M3: 0 | N3: 0 | O3: not identified | P3: 0 | Q3: 0 | R3: 0 | U3: none_identified | V3: 0 | X3: no_statewide_ivf_treatment_eligibility_rule_identified | Y3: no_statewide_ivf_treatment_eligibility_rule_identified | Z3: no_statewide_ivf_treatment_eligibility_rule_identified | AA3: not_applicable_no_statewide_ivf_treatment_mandate | AB3: not_applicable_no_statewide_ivf_treatment_mandate | AC3: none stated in source used | AD3: no_statewide_ivf_treatment_eligibility_rule_identified | AE3: no_statewide_ivf_treatment_eligibility_rule_identified | AF3: no_statewide_ivf_treatment_eligibility_rule_identified | AG3: no_statewide_ivf_treatment_eligibility_rule_identified | AH3: not_identified_in_secondary_sources_used | AI3: not_identified_in_secondary_sources_used | AJ3: not_identified_in_secondary_sources_used | AK3: not_identified_in_secondary_sources_used | AL3: not_identified_in_secondary_sources_used | AM3: restricted | AN3: unclear | AO3: no_or_unclear | AP3: unclear | AQ3: adoption or post-birth process often required | AR3: no_fertility_specific_state_clinic_license_coded_in_this_pass | AS3: federal_CDC_NASS_reporting_baseline | AT3: federal_FCSRCA_CDC_public_reporting | AU3: CLIA_CMS_FDA_baseline; state_variation_not_fully_coded | AV3: 0 | AW3: 0 | AX3: 0 | AY3: =BU3 -> 38 | AZ3: 1 | BA3: 192 | BB3: 740133 | BC3: FFM | BD3: divided_government | BE3: supportive_or_protective | BF3: No statewide infertility/IVF mandate identified in Triage Cancer state-law chart | BG3: https://triagecancer.org/state-laws/health-insurance-fertility-services | BH3: https://triagecancer.org/state-laws/health-insurance-fertility-services; https://surrogacy360.org/wp-content/uploads/2024/08/Regulation-Details-in-the-US-by-State_8.6.24.pdf; https://www.asrm.org/advocacy-and-policy/reproductive-rights/summary-reports/state-abortion-laws-potential-implications-for-reproductive-medicine/; https://www.guttmacher.org/2025/12/state-policy-trends-2025-full-year-analysis; https://www.cdc.gov/art/php/nass/index.html; https://www.cdc.gov/art/success-rates/index.html; https://www.cms.gov/medicare/quality/clinical-laboratory-improvement-amendments; https://www.cms.gov/marketplace/in-person-assisters/training-webinars/training/marketplaces-map; https://ballotpedia.org/State_government_trifectas; https://www.britannica.com/topic/largest-U-S-state-by-population; https://www.guttmacher.org/united-states/abortion | BI3: Starter row only. Needs primary-law verification for Medicaid, public funding, eligibility, embryo rules, surrogacy, clinic regulation, and utilization variables. Surrogacy fields coded from Surrogacy360 2024 state-by-state summary; interpret as starter classification requiring legal review for publication. Eligibility/LGBTQ fields on this row were filled as a 2026 starter classification based on absence of a statewide IVF-treatment mandate or unclear scope in the source used; this should not be interpreted as a full review of all private plans or clinic access in the state. Embryo/personhood/disposition fields were filled conservatively in this pass. Unless a state had a clear embryo-specific rule in the secondary sources used, values were set to not_identified_in_secondary_sources_used rather than treated as definitive absence of law. Clinic/reporting fields in this pass were coded from federal baselines: CDC NASS/FCSRCA reporting and CMS CLIA materials; insurance marketplace type from CMS Plan Year 2026 marketplace map; political control from Ballotpedia current trifecta status; population uses 2024 state estimate table summarized by Britannica from U.S. Census data. IVF clinic counts and cycle counts remain blank pending direct state-level CDC extraction. | BJ3: RRM | BK3: partially_filled_needs_primary_law_review | BL3: =IFERROR((AZ3/BB3)*1000000,0) -> 1.3511085 | BM3: =IFERROR((BA3/BB3)*1000000,0) -> 259.41284 | BN3: =IFERROR(VLOOKUP(H3,index_logic!$A$4:$B$8,2,FALSE),0) -> 0 | BO3: =IFERROR(VLOOKUP(AD3,index_logic!$D$4:$E$21,2,FALSE),0) -> 3 | BP3: =IFERROR(VLOOKUP(AM3,index_logic!$G$4:$H$6,2,FALSE),0) -> 3 | BQ3: =IFERROR(VLOOKUP(AH3,index_logic!$J$4:$K$6,2,FALSE),0) -> 15 | BR3: =IFERROR(VLOOKUP(BE3,index_logic!$M$4:$N$7,2,FALSE),0) -> 10 | BS3: =IFERROR(VLOOKUP(BL3,index_logic!$P$4:$Q$9,2,TRUE),0) -> 5 | BT3: =IFERROR(VLOOKUP(BM3,index_logic!$S$4:$T$9,2,TRUE),0) -> 2 | BU3: =BN3+BO3+BP3+BQ3+BR3+BS3+BT3 -> 38 | BV3: =IF(BU3>=80,"Very High",IF(BU3>=65,"High",IF(BU3>=50,"Moderate",IF(BU3>=35,"Low","Very Low")))) -> Low
A4: Arizona | B4: AZ | C4: 2026 | D4: current_snapshot | E4: 0 | F4: NA | G4: 2026-03-12 | H4: none_identified | I4: No statewide infertility/IVF coverage mandate identified in source used | J4: no_statewide_ivf_mandate_identified | K4: 0 | L4: 0 | M4: 0 | N4: 0 | O4: not identified | P4: 0 | Q4: 0 | R4: 0 | U4: none_identified | V4: 0 | X4: no_statewide_ivf_treatment_eligibility_rule_identified | Y4: no_statewide_ivf_treatment_eligibility_rule_identified | Z4: no_statewide_ivf_treatment_eligibility_rule_identified | AA4: not_applicable_no_statewide_ivf_treatment_mandate | AB4: not_applicable_no_statewide_ivf_treatment_mandate | AC4: none stated in source used | AD4: no_statewide_ivf_treatment_eligibility_rule_identified | AE4: no_statewide_ivf_treatment_eligibility_rule_identified | AF4: no_statewide_ivf_treatment_eligibility_rule_identified | AG4: no_statewide_ivf_treatment_eligibility_rule_identified | AH4: not_identified_in_secondary_sources_used | AI4: not_identified_in_secondary_sources_used | AJ4: not_identified_in_secondary_sources_used | AK4: not_identified_in_secondary_sources_used | AL4: not_identified_in_secondary_sources_used | AM4: restricted | AN4: unclear | AO4: limited | AP4: unclear | AQ4: limited court recognition; extra conditions apply | AR4: no_fertility_specific_state_clinic_license_coded_in_this_pass | AS4: federal_CDC_NASS_reporting_baseline | AT4: federal_FCSRCA_CDC_public_reporting | AU4: CLIA_CMS_FDA_baseline; state_variation_not_fully_coded | AV4: 0 | AW4: 0 | AX4: 0 | AY4: =BU4 -> 31 | AZ4: 10 | BA4: 3680 | BB4: 7582384 | BC4: FFM | BD4: divided_government | BE4: restrictive | BF4: No statewide infertility/IVF mandate identified in Triage Cancer state-law chart | BG4: https://triagecancer.org/state-laws/health-insurance-fertility-services | BH4: https://triagecancer.org/state-laws/health-insurance-fertility-services; https://surrogacy360.org/wp-content/uploads/2024/08/Regulation-Details-in-the-US-by-State_8.6.24.pdf; https://www.asrm.org/advocacy-and-policy/reproductive-rights/summary-reports/state-abortion-laws-potential-implications-for-reproductive-medicine/; https://www.guttmacher.org/2025/12/state-policy-trends-2025-full-year-analysis; https://www.cdc.gov/art/php/nass/index.html; https://www.cdc.gov/art/success-rates/index.html; https://www.cms.gov/medicare/quality/clinical-laboratory-improvement-amendments; https://www.cms.gov/marketplace/in-person-assisters/training-webinars/training/marketplaces-map; https://ballotpedia.org/State_government_trifectas; https://www.britannica.com/topic/largest-U-S-state-by-population; https://www.guttmacher.org/united-states/abortion | BI4: Starter row only. Needs primary-law verification for Medicaid, public funding, eligibility, embryo rules, surrogacy, clinic regulation, and utilization variables. Surrogacy fields coded from Surrogacy360 2024 state-by-state summary; interpret as starter classification requiring legal review for publication. Eligibility/LGBTQ fields on this row were filled as a 2026 starter classification based on absence of a statewide IVF-treatment mandate or unclear scope in the source used; this should not be interpreted as a full review of all private plans or clinic access in the state. Embryo/personhood/disposition fields were filled conservatively in this pass. Unless a state had a clear embryo-specific rule in the secondary sources used, values were set to not_identified_in_secondary_sources_used rather than treated as definitive absence of law. Clinic/reporting fields in this pass were coded from federal baselines: CDC NASS/FCSRCA reporting and CMS CLIA materials; insurance marketplace type from CMS Plan Year 2026 marketplace map; political control from Ballotpedia current trifecta status; population uses 2024 state estimate table summarized by Britannica from U.S. Census data. IVF clinic counts and cycle counts remain blank pending direct state-level CDC extraction. | BJ4: RRM | BK4: partially_filled_needs_primary_law_review | BL4: =IFERROR((AZ4/BB4)*1000000,0) -> 1.3188464 | BM4: =IFERROR((BA4/BB4)*1000000,0) -> 485.33548 | BN4: =IFERROR(VLOOKUP(H4,index_logic!$A$4:$B$8,2,FALSE),0) -> 0 | BO4: =IFERROR(VLOOKUP(AD4,index_logic!$D$4:$E$21,2,FALSE),0) -> 3 | BP4: =IFERROR(VLOOKUP(AM4,index_logic!$G$4:$H$6,2,FALSE),0) -> 3 | BQ4: =IFERROR(VLOOKUP(AH4,index_logic!$J$4:$K$6,2,FALSE),0) -> 15 | BR4: =IFERROR(VLOOKUP(BE4,index_logic!$M$4:$N$7,2,FALSE),0) -> 3 | BS4: =IFERROR(VLOOKUP(BL4,index_logic!$P$4:$Q$9,2,TRUE),0) -> 5 | BT4: =IFERROR(VLOOKUP(BM4,index_logic!$S$4:$T$9,2,TRUE),0) -> 2 | BU4: =BN4+BO4+BP4+BQ4+BR4+BS4+BT4 -> 31 | BV4: =IF(BU4>=80,"Very High",IF(BU4>=65,"High",IF(BU4>=50,"Moderate",IF(BU4>=35,"Low","Very Low")))) -> Very Low
A5: Arkansas | B5: AR | C5: 2026 | D5: active | E5: 1987 | F5: NA | G5: 2026-03-12 | H5: cover | I5: IVF coverage in individual and group policies with maternity benefits (except HMOs) | J5: IVF-specific | K5: not specified | L5: $15,000 lifetime maximum | M5: 15000 | N5: unclear | O5: not identified | P5: not specified | Q5: not specified | R5: not identified | S5: not identified | T5: not identified | U5: none_identified | V5: 0 | W5: not identified | X5: married_spousal_gametes_required | Y5: 2 years unexplained infertility or specified medical conditions | Z5: must first fail less costly covered infertility treatment | AA5: not specified in source used | AB5: not specified in source used | AC5: none stated in source used | AD5: restricted_spouse_and_spousal_sperm_requirement | AE5: excluded_spouse_required | AF5: not explicitly addressed; sex/marriage-linked eligibility | AG5: patient oocytes must be fertilized with spouse sperm | AH5: not_identified_in_secondary_sources_used | AI5: not_identified_in_secondary_sources_used | AJ5: not_identified_in_secondary_sources_used | AK5: not_identified_in_secondary_sources_used | AL5: not_identified_in_secondary_sources_used | AM5: restricted | AN5: unclear | AO5: no_or_unclear | AP5: unclear | AQ5: adoption or post-birth process often required | AR5: no_fertility_specific_state_clinic_license_coded_in_this_pass | AS5: federal_CDC_NASS_reporting_baseline | AT5: federal_FCSRCA_CDC_public_reporting | AU5: CLIA_CMS_FDA_baseline; state_variation_not_fully_coded | AV5: 1987 | AW5: 2026 | AX5: 0 | AY5: =BU5 -> 52 | AZ5: 1 | BA5: 1113 | BB5: 3088354 | BC5: SBM-FP | BD5: republican_trifecta | BE5: near_total_ban_or_total_ban_environment | BF5: AR Code § 23-85-137 | BG5: https://law.justia.com/codes/arkansas/title-23/subtitle-3/chapter-85/section-23-85-137/ | BH5: https://triagecancer.org/state-laws/health-insurance-fertility-services; https://surrogacy360.org/wp-content/uploads/2024/08/Regulation-Details-in-the-US-by-State_8.6.24.pdf; https://www.reproductivefacts.org/patient-advocacy/state-and-territory-infertility-insurance-laws/arkansas/; https://www.asrm.org/advocacy-and-policy/reproductive-rights/summary-reports/state-abortion-laws-potential-implications-for-reproductive-medicine/; https://www.guttmacher.org/2025/12/state-policy-trends-2025-full-year-analysis; https://www.cdc.gov/art/php/nass/index.html; https://www.cdc.gov/art/success-rates/index.html; https://www.cms.gov/medicare/quality/clinical-laboratory-improvement-amendments; https://www.cms.gov/marketplace/in-person-assisters/training-webinars/training/marketplaces-map; https://ballotpedia.org/State_government_trifectas; https://www.britannica.com/topic/largest-U-S-state-by-population; https://www.guttmacher.org/united-states/abortion | BI5: Triage chart says IVF required; cryopreservation included; $15,000 lifetime max; coverage applies to policies with maternity benefits except HMOs. Surrogacy fields coded from Surrogacy360 2024 state-by-state summary; interpret as starter classification requiring legal review for publication. Eligibility/LGBTQ fields updated in this pass using current 2026 state-law summaries and/or statute text where available; some entries remain conservative where the source did not clearly resolve LGBTQ or gender-identity treatment eligibility. Embryo/personhood/disposition fields were filled conservatively in this pass. Unless a state had a clear embryo-specific rule in the secondary sources used, values were set to not_identified_in_secondary_sources_used rather than treated as definitive absence of law. Clinic/reporting fields in this pass were coded from federal baselines: CDC NASS/FCSRCA reporting and CMS CLIA materials; insurance marketplace type from CMS Plan Year 2026 marketplace map; political control from Ballotpedia current trifecta status; population uses 2024 state estimate table summarized by Britannica from U.S. Census data. IVF clinic counts and cycle counts remain blank pending direct state-level CDC extraction. | BJ5: RRM | BK5: partially_filled_needs_primary_law_review | BL5: =IFERROR((AZ5/BB5)*1000000,0) -> 0.32379708 | BM5: =IFERROR((BA5/BB5)*1000000,0) -> 360.38615 | BN5: =IFERROR(VLOOKUP(H5,index_logic!$A$4:$B$8,2,FALSE),0) -> 30 | BO5: =IFERROR(VLOOKUP(AD5,index_logic!$D$4:$E$21,2,FALSE),0) -> 0 | BP5: =IFERROR(VLOOKUP(AM5,index_logic!$G$4:$H$6,2,FALSE),0) -> 3 | BQ5: =IFERROR(VLOOKUP(AH5,index_logic!$J$4:$K$6,2,FALSE),0) -> 15 | BR5: =IFERROR(VLOOKUP(BE5,index_logic!$M$4:$N$7,2,FALSE),0) -> 0 | BS5: =IFERROR(VLOOKUP(BL5,index_logic!$P$4:$Q$9,2,TRUE),0) -> 2 | BT5: =IFERROR(VLOOKUP(BM5,index_logic!$S$4:$T$9,2,TRUE),0) -> 2 | BU5: =BN5+BO5+BP5+BQ5+BR5+BS5+BT5 -> 52 | BV5: =IF(BU5>=80,"Very High",IF(BU5>=65,"High",IF(BU5>=50,"Moderate",IF(BU5>=35,"Low","Very Low")))) -> Moderate
A6: California | B6: CA | C6: 2026 | D6: active | E6: 2026 | F6: NA | G6: 2026-03-12 | H6: mixed_cover_offer | I6: Large group must cover infertility diagnosis/treatment incl IVF; small group must offer coverage | J6: Infertility + IVF (large group); offer-only for small group | K6: 3 oocyte retrievals | L6: not specified | M6: not specified | N6: yes | O6: yes | P6: not specified | Q6: Unlimited embryo transfers under ASRM guidelines | R6: yes | S6: excluded for Medi-Cal managed care | T6: Medi-Cal managed care excluded from SB 729 infertility coverage | U6: none_identified | V6: 0 | W6: CalPERS plans exempt until 2027-07-01 | X6: none stated | Y6: broad definition noted by source; includes same-sex couples and single people | Z6: none stated in source used | AA6: not specified in source used | AB6: not specified in source used | AC6: none stated in source used | AD6: explicitly inclusive | AE6: explicitly inclusive | AF6: not explicitly addressed in source used | AG6: none stated in source used | AH6: not_identified_in_secondary_sources_used | AI6: not_identified_in_secondary_sources_used | AJ6: not_identified_in_secondary_sources_used | AK6: not_identified_in_secondary_sources_used | AL6: not_identified_in_secondary_sources_used | AM6: legal | AN6: yes | AO6: yes | AP6: yes | AQ6: court-recognized parentage available | AR6: no_fertility_specific_state_clinic_license_coded_in_this_pass | AS6: federal_CDC_NASS_reporting_baseline | AT6: federal_FCSRCA_CDC_public_reporting | AU6: CLIA_CMS_FDA_baseline; state_variation_not_fully_coded | AV6: 2024 | AW6: 2026 | AX6: 0 | AY6: =BU6 -> 88 | AZ6: 85 | BA6: 63018 | BB6: 39431263 | BC6: SBM | BD6: democratic_trifecta | BE6: supportive_or_protective | BF6: SB 729 (2024); SB 600 (2019) | BG6: https://leginfo.legislature.ca.gov/faces/billTextClient.xhtml?bill_id=202320240SB729 | BH6: https://triagecancer.org/state-laws/health-insurance-fertility-services; https://surrogacy360.org/wp-content/uploads/2024/08/Regulation-Details-in-the-US-by-State_8.6.24.pdf; https://calmatters.org/newsletter/ivf-law-expansion/; https://www.asrm.org/advocacy-and-policy/reproductive-rights/summary-reports/state-abortion-laws-potential-implications-for-reproductive-medicine/; https://www.guttmacher.org/2025/12/state-policy-trends-2025-full-year-analysis; https://www.cdc.gov/art/php/nass/index.html; https://www.cdc.gov/art/success-rates/index.html; https://www.cms.gov/medicare/quality/clinical-laboratory-improvement-amendments; https://www.cms.gov/marketplace/in-person-assisters/training-webinars/training/marketplaces-map; https://ballotpedia.org/State_government_trifectas; https://www.britannica.com/topic/largest-U-S-state-by-population; https://www.guttmacher.org/united-states/abortion | BI6: Triage notes implementation delayed to 2026-01-01 from 2025-07-01; source also lists fertility preservation coverage under SB 600. Surrogacy fields coded from Surrogacy360 2024 state-by-state summary; interpret as starter classification requiring legal review for publication. Eligibility/LGBTQ fields updated in this pass using current 2026 state-law summaries and/or statute text where available; some entries remain conservative where the source did not clearly resolve LGBTQ or gender-identity treatment eligibility. Embryo/personhood/disposition fields were filled conservatively in this pass. Unless a state had a clear embryo-specific rule in the secondary sources used, values were set to not_identified_in_secondary_sources_used rather than treated as definitive absence of law. Clinic/reporting fields in this pass were coded from federal baselines: CDC NASS/FCSRCA reporting and CMS CLIA materials; insurance marketplace type from CMS Plan Year 2026 marketplace map; political control from Ballotpedia current trifecta status; population uses 2024 state estimate table summarized by Britannica from U.S. Census data. IVF clinic counts and cycle counts remain blank pending direct state-level CDC extraction. | BJ6: RRM | BK6: partially_filled_needs_primary_law_review | BL6: =IFERROR((AZ6/BB6)*1000000,0) -> 2.1556499 | BM6: =IFERROR((BA6/BB6)*1000000,0) -> 1598.1735 | BN6: =IFERROR(VLOOKUP(H6,index_logic!$A$4:$B$8,2,FALSE),0) -> 22 | BO6: =IFERROR(VLOOKUP(AD6,index_logic!$D$4:$E$21,2,FALSE),0) -> 20 | BP6: =IFERROR(VLOOKUP(AM6,index_logic!$G$4:$H$6,2,FALSE),0) -> 10 | BQ6: =IFERROR(VLOOKUP(AH6,index_logic!$J$4:$K$6,2,FALSE),0) -> 15 | BR6: =IFERROR(VLOOKUP(BE6,index_logic!$M$4:$N$7,2,FALSE),0) -> 10 | BS6: =IFERROR(VLOOKUP(BL6,index_logic!$P$4:$Q$9,2,TRUE),0) -> 5 | BT6: =IFERROR(VLOOKUP(BM6,index_logic!$S$4:$T$9,2,TRUE),0) -> 6 | BU6: =BN6+BO6+BP6+BQ6+BR6+BS6+BT6 -> 88 | BV6: =IF(BU6>=80,"Very High",IF(BU6>=65,"High",IF(BU6>=50,"Moderate",IF(BU6>=35,"Low","Very Low")))) -> Very High
A7: Colorado | B7: CO | C7: 2026 | D7: active | E7: 2022 | F7: NA | G7: 2026-03-12 | H7: cover | I7: Infertility diagnosis, treatment, and standard fertility preservation | J7: Comprehensive infertility + IVF | K7: 3 oocyte retrievals | L7: not specified | M7: not specified | N7: yes | O7: yes | P7: not specified | Q7: Unlimited embryo transfers under ASRM guidelines | R7: yes | S7: not identified | T7: not identified | U7: none_identified | V7: 0 | W7: not identified | X7: none stated | Y7: includes inability to reproduce as an individual or with the person's partner | Z7: none stated in source used | AA7: no arbitrary age limit allowed | AB7: no arbitrary age limit allowed | AC7: none stated in source used | AD7: inclusive gender-neutral definition | AE7: inclusive individual-or-partner definition | AF7: gender-neutral definition; no explicit gender-identity clause cited | AG7: none stated in source used | AH7: not_identified_in_secondary_sources_used | AI7: not_identified_in_secondary_sources_used | AJ7: not_identified_in_secondary_sources_used | AK7: not_identified_in_secondary_sources_used | AL7: not_identified_in_secondary_sources_used | AM7: legal | AN7: yes | AO7: yes | AP7: no | AQ7: court-recognized parentage available | AR7: no_fertility_specific_state_clinic_license_coded_in_this_pass | AS7: federal_CDC_NASS_reporting_baseline | AT7: federal_FCSRCA_CDC_public_reporting | AU7: CLIA_CMS_FDA_baseline; state_variation_not_fully_coded | AV7: 2020 | AW7: 2022 | AX7: 0 | AY7: =BU7 -> 92 | AZ7: 11 | BA7: 5258 | BB7: 5957493 | BC7: SBM | BD7: democratic_trifecta | BE7: supportive_or_protective | BF7: HB20-1158 (Colorado Building Families Act) | BG7: https://leg.colorado.gov/bills/hb20-1158 | BH7: https://triagecancer.org/state-laws/health-insurance-fertility-services; https://surrogacy360.org/wp-content/uploads/2024/08/Regulation-Details-in-the-US-by-State_8.6.24.pdf; https://www.reproductivefacts.org/patient-advocacy/state-and-territory-infertility-insurance-laws/colorado/; https://www.asrm.org/advocacy-and-policy/reproductive-rights/summary-reports/state-abortion-laws-potential-implications-for-reproductive-medicine/; https://www.guttmacher.org/2025/12/state-policy-trends-2025-full-year-analysis; https://www.cdc.gov/art/php/nass/index.html; https://www.cdc.gov/art/success-rates/index.html; https://www.cms.gov/medicare/quality/clinical-laboratory-improvement-amendments; https://www.cms.gov/marketplace/in-person-assisters/training-webinars/training/marketplaces-map; https://ballotpedia.org/State_government_trifectas; https://www.britannica.com/topic/largest-U-S-state-by-population; https://www.guttmacher.org/united-states/abortion | BI7: Triage notes individual/small-group coverage may depend on federal cost-defrayal determinations. Surrogacy fields coded from Surrogacy360 2024 state-by-state summary; interpret as starter classification requiring legal review for publication. Eligibility/LGBTQ fields updated in this pass using current 2026 state-law summaries and/or statute text where available; some entries remain conservative where the source did not clearly resolve LGBTQ or gender-identity treatment eligibility. Embryo/personhood/disposition fields were filled conservatively in this pass. Unless a state had a clear embryo-specific rule in the secondary sources used, values were set to not_identified_in_secondary_sources_used rather than treated as definitive absence of law. Clinic/reporting fields in this pass were coded from federal baselines: CDC NASS/FCSRCA reporting and CMS CLIA materials; insurance marketplace type from CMS Plan Year 2026 marketplace map; political control from Ballotpedia current trifecta status; population uses 2024 state estimate table summarized by Britannica from U.S. Census data. IVF clinic counts and cycle counts remain blank pending direct state-level CDC extraction. | BJ7: RRM | BK7: partially_filled_needs_primary_law_review | BL7: =IFERROR((AZ7/BB7)*1000000,0) -> 1.8464143 | BM7: =IFERROR((BA7/BB7)*1000000,0) -> 882.58601 | BN7: =IFERROR(VLOOKUP(H7,index_logic!$A$4:$B$8,2,FALSE),0) -> 30 | BO7: =IFERROR(VLOOKUP(AD7,index_logic!$D$4:$E$21,2,FALSE),0) -> 18 | BP7: =IFERROR(VLOOKUP(AM7,index_logic!$G$4:$H$6,2,FALSE),0) -> 10 | BQ7: =IFERROR(VLOOKUP(AH7,index_logic!$J$4:$K$6,2,FALSE),0) -> 15 | BR7: =IFERROR(VLOOKUP(BE7,index_logic!$M$4:$N$7,2,FALSE),0) -> 10 | BS7: =IFERROR(VLOOKUP(BL7,index_logic!$P$4:$Q$9,2,TRUE),0) -> 5 | BT7: =IFERROR(VLOOKUP(BM7,index_logic!$S$4:$T$9,2,TRUE),0) -> 4 | BU7: =BN7+BO7+BP7+BQ7+BR7+BS7+BT7 -> 92 | BV7: =IF(BU7>=80,"Very High",IF(BU7>=65,"High",IF(BU7>=50,"Moderate",IF(BU7>=35,"Low","Very Low")))) -> Very High
A8: Connecticut | B8: CT | C8: 2026 | D8: active | E8: 2018 | F8: NA | G8: 2026-03-12 | H8: cover | I8: Medically necessary infertility diagnosis and treatment, including IVF | J8: Infertility + IVF | K8: lifetime cycle limits apply (source does not specify count) | L8: lifetime cycle limits | M8: not specified | N8: yes | O8: yes | P8: not specified | Q8: not specified | R8: yes | S8: not identified | T8: not identified | U8: none_identified | V8: 0 | W8: not identified | X8: none stated | Y8: individual unable to conceive, produce conception, or sustain successful pregnancy during 1-year period, or treatment is medically necessary | Z8: less expensive medically viable treatment first before IVF/GIFT/ZIFT/low tubal ovum transfer unless likely unsuccessful | AA8: up to age 40 for IVF-related services | AB8: not specified in source used | AC8: none stated in source used | AD8: gender-neutral individual definition; not explicitly addressed beyond that | AE8: likely inclusive via individual definition | AF8: not explicitly addressed in source used | AG8: none stated in source used | AH8: not_identified_in_secondary_sources_used | AI8: not_identified_in_secondary_sources_used | AJ8: not_identified_in_secondary_sources_used | AK8: not_identified_in_secondary_sources_used | AL8: not_identified_in_secondary_sources_used | AM8: legal | AN8: yes | AO8: yes | AP8: no | AQ8: court-recognized parentage available | AR8: no_fertility_specific_state_clinic_license_coded_in_this_pass | AS8: federal_CDC_NASS_reporting_baseline | AT8: federal_FCSRCA_CDC_public_reporting | AU8: CLIA_CMS_FDA_baseline; state_variation_not_fully_coded | AV8: 2017 | AW8: 2018 | AX8: 0 | AY8: =BU8 -> 88 | AZ8: 7 | BA8: 4497 | BB8: 3675069 | BC8: SBM | BD8: democratic_trifecta | BE8: supportive_or_protective | BF8: HB 7124 (2017) | BG8: https://www.cga.ct.gov/asp/cgabillstatus/cgabillstatus.asp?selBillType=Bill&bill_num=HB07124&which_year=2017 | BH8: https://triagecancer.org/state-laws/health-insurance-fertility-services; https://surrogacy360.org/wp-content/uploads/2024/08/Regulation-Details-in-the-US-by-State_8.6.24.pdf; https://www.reproductivefacts.org/patient-advocacy/state-and-territory-infertility-insurance-laws/connecticut/; https://www.asrm.org/advocacy-and-policy/reproductive-rights/summary-reports/state-abortion-laws-potential-implications-for-reproductive-medicine/; https://www.guttmacher.org/2025/12/state-policy-trends-2025-full-year-analysis; https://www.cdc.gov/art/php/nass/index.html; https://www.cdc.gov/art/success-rates/index.html; https://www.cms.gov/medicare/quality/clinical-laboratory-improvement-amendments; https://www.cms.gov/marketplace/in-person-assisters/training-webinars/training/marketplaces-map; https://ballotpedia.org/State_government_trifectas; https://www.britannica.com/topic/largest-U-S-state-by-population; https://www.guttmacher.org/united-states/abortion | BI8: Source notes age cap up to 40 and requirement to try less costly treatments first. Surrogacy fields coded from Surrogacy360 2024 state-by-state summary; interpret as starter classification requiring legal review for publication. Eligibility/LGBTQ fields updated in this pass using current 2026 state-law summaries and/or statute text where available; some entries remain conservative where the source did not clearly resolve LGBTQ or gender-identity treatment eligibility. Embryo/personhood/disposition fields were filled conservatively in this pass. Unless a state had a clear embryo-specific rule in the secondary sources used, values were set to not_identified_in_secondary_sources_used rather than treated as definitive absence of law. Clinic/reporting fields in this pass were coded from federal baselines: CDC NASS/FCSRCA reporting and CMS CLIA materials; insurance marketplace type from CMS Plan Year 2026 marketplace map; political control from Ballotpedia current trifecta status; population uses 2024 state estimate table summarized by Britannica from U.S. Census data. IVF clinic counts and cycle counts remain blank pending direct state-level CDC extraction. | BJ8: RRM | BK8: partially_filled_needs_primary_law_review | BL8: =IFERROR((AZ8/BB8)*1000000,0) -> 1.9047261 | BM8: =IFERROR((BA8/BB8)*1000000,0) -> 1223.6505 | BN8: =IFERROR(VLOOKUP(H8,index_logic!$A$4:$B$8,2,FALSE),0) -> 30 | BO8: =IFERROR(VLOOKUP(AD8,index_logic!$D$4:$E$21,2,FALSE),0) -> 12 | BP8: =IFERROR(VLOOKUP(AM8,index_logic!$G$4:$H$6,2,FALSE),0) -> 10 | BQ8: =IFERROR(VLOOKUP(AH8,index_logic!$J$4:$K$6,2,FALSE),0) -> 15 | BR8: =IFERROR(VLOOKUP(BE8,index_logic!$M$4:$N$7,2,FALSE),0) -> 10 | BS8: =IFERROR(VLOOKUP(BL8,index_logic!$P$4:$Q$9,2,TRUE),0) -> 5 | BT8: =IFERROR(VLOOKUP(BM8,index_logic!$S$4:$T$9,2,TRUE),0) -> 6 | BU8: =BN8+BO8+BP8+BQ8+BR8+BS8+BT8 -> 88 | BV8: =IF(BU8>=80,"Very High",IF(BU8>=65,"High",IF(BU8>=50,"Moderate",IF(BU8>=35,"Low","Very Low")))) -> Very High
A9: Delaware | B9: DE | C9: 2026 | D9: active | E9: 2018 | F9: NA | G9: 2026-03-12 | H9: cover | I9: Infertility diagnosis and treatment including IVF + fertility preservation | J9: Comprehensive infertility + IVF | K9: 6 completed egg retrievals per lifetime | L9: 6 egg retrievals lifetime | M9: not specified | N9: yes | O9: yes | P9: not specified | Q9: Unlimited embryo transfers under ASRM guidelines | R9: not identified | S9: not identified | T9: not identified | U9: none_identified | V9: 0 | W9: not identified | X9: none stated | Y9: individual unable to procreate or carry pregnancy to live birth | Z9: reasonable effort with less costly covered treatment first; no more than 3 ovulation induction or IUI cycles before IVF unless IVF medically necessary | AA9: retrieval before 45; transfer before 50 | AB9: not specified in source used | AC9: none stated in source used | AD9: inclusive individual definition and coverage extends to non-spouse dependents | AE9: likely inclusive individual definition | AF9: not explicitly addressed in source used | AG9: none stated in source used | AH9: not_identified_in_secondary_sources_used | AI9: not_identified_in_secondary_sources_used | AJ9: not_identified_in_secondary_sources_used | AK9: not_identified_in_secondary_sources_used | AL9: not_identified_in_secondary_sources_used | AM9: legal | AN9: yes | AO9: yes | AP9: yes_or_unspecified_genetic | AQ9: court-recognized parentage available | AR9: no_fertility_specific_state_clinic_license_coded_in_this_pass | AS9: federal_CDC_NASS_reporting_baseline | AT9: federal_FCSRCA_CDC_public_reporting | AU9: CLIA_CMS_FDA_baseline; state_variation_not_fully_coded | AV9: 2018 | AW9: 2018 | AX9: 0 | AY9: =BU9 -> 92 | AZ9: 2 | BA9: 1076 | BB9: 1051917 | BC9: FFM | BD9: democratic_trifecta | BE9: supportive_or_protective | BF9: S 139 (2018) | BG9: https://legis.delaware.gov/BillDetail?LegislationId=26219 | BH9: https://triagecancer.org/state-laws/health-insurance-fertility-services; https://surrogacy360.org/wp-content/uploads/2024/08/Regulation-Details-in-the-US-by-State_8.6.24.pdf; https://www.reproductivefacts.org/patient-advocacy/state-and-territory-infertility-insurance-laws/delaware/; https://www.asrm.org/advocacy-and-policy/reproductive-rights/summary-reports/state-abortion-laws-potential-implications-for-reproductive-medicine/; https://www.guttmacher.org/2025/12/state-policy-trends-2025-full-year-analysis; https://www.cdc.gov/art/php/nass/index.html; https://www.cdc.gov/art/success-rates/index.html; https://www.cms.gov/medicare/quality/clinical-laboratory-improvement-amendments; https://www.cms.gov/marketplace/in-person-assisters/training-webinars/training/marketplaces-map; https://ballotpedia.org/State_government_trifectas; https://www.britannica.com/topic/largest-U-S-state-by-population; https://www.guttmacher.org/united-states/abortion | BI9: Source says insurers may not impose different cost sharing or restrictions compared with other medical services. Surrogacy fields coded from Surrogacy360 2024 state-by-state summary; interpret as starter classification requiring legal review for publication. Eligibility/LGBTQ fields updated in this pass using current 2026 state-law summaries and/or statute text where available; some entries remain conservative where the source did not clearly resolve LGBTQ or gender-identity treatment eligibility. Embryo/personhood/disposition fields were filled conservatively in this pass. Unless a state had a clear embryo-specific rule in the secondary sources used, values were set to not_identified_in_secondary_sources_used rather than treated as definitive absence of law. Clinic/reporting fields in this pass were coded from federal baselines: CDC NASS/FCSRCA reporting and CMS CLIA materials; insurance marketplace type from CMS Plan Year 2026 marketplace map; political control from Ballotpedia current trifecta status; population uses 2024 state estimate table summarized by Britannica from U.S. Census data. IVF clinic counts and cycle counts remain blank pending direct state-level CDC extraction. | BJ9: RRM | BK9: partially_filled_needs_primary_law_review | BL9: =IFERROR((AZ9/BB9)*1000000,0) -> 1.9012907 | BM9: =IFERROR((BA9/BB9)*1000000,0) -> 1022.8944 | BN9: =IFERROR(VLOOKUP(H9,index_logic!$A$4:$B$8,2,FALSE),0) -> 30 | BO9: =IFERROR(VLOOKUP(AD9,index_logic!$D$4:$E$21,2,FALSE),0) -> 18 | BP9: =IFERROR(VLOOKUP(AM9,index_logic!$G$4:$H$6,2,FALSE),0) -> 10 | BQ9: =IFERROR(VLOOKUP(AH9,index_logic!$J$4:$K$6,2,FALSE),0) -> 15 | BR9: =IFERROR(VLOOKUP(BE9,index_logic!$M$4:$N$7,2,FALSE),0) -> 10 | BS9: =IFERROR(VLOOKUP(BL9,index_logic!$P$4:$Q$9,2,TRUE),0) -> 5 | BT9: =IFERROR(VLOOKUP(BM9,index_logic!$S$4:$T$9,2,TRUE),0) -> 4 | BU9: =BN9+BO9+BP9+BQ9+BR9+BS9+BT9 -> 92 | BV9: =IF(BU9>=80,"Very High",IF(BU9>=65,"High",IF(BU9>=50,"Moderate",IF(BU9>=35,"Low","Very Low")))) -> Very High
A10: Florida | B10: FL | C10: 2026 | D10: active | E10: 0 | F10: NA | G10: 2026-03-12 | H10: none_for_ivf | I10: No statewide infertility/IVF coverage mandate identified in source; fertility preservation law only | J10: fertility_preservation_only | K10: 0 | L10: 0 | M10: 0 | N10: 0 | O10: yes | P10: 0 | Q10: 0 | R10: 0 | S10: not identified | T10: not identified | U10: none_identified | V10: 0 | W10: fertility_preservation_only in state group plan | X10: no_statewide_ivf_treatment_rule_identified_fertility_preservation_only_law | Y10: no_statewide_ivf_treatment_rule_identified_fertility_preservation_only_law | Z10: no_statewide_ivf_treatment_rule_identified_fertility_preservation_only_law | AA10: not_applicable_no_statewide_ivf_treatment_mandate | AB10: not_applicable_no_statewide_ivf_treatment_mandate | AC10: none stated in source used | AD10: no_statewide_ivf_treatment_rule_identified_fertility_preservation_only_law | AE10: no_statewide_ivf_treatment_rule_identified_fertility_preservation_only_law | AF10: no_statewide_ivf_treatment_rule_identified_fertility_preservation_only_law | AG10: no_statewide_ivf_treatment_rule_identified_fertility_preservation_only_law | AH10: not_identified_in_secondary_sources_used | AI10: not_identified_in_secondary_sources_used | AJ10: not_identified_in_secondary_sources_used | AK10: not_identified_in_secondary_sources_used | AL10: not_identified_in_secondary_sources_used | AM10: restricted | AN10: limited_expense_payment | AO10: limited | AP10: unclear | AQ10: limited court recognition; extra conditions apply | AR10: no_fertility_specific_state_clinic_license_coded_in_this_pass | AS10: federal_CDC_NASS_reporting_baseline | AT10: federal_FCSRCA_CDC_public_reporting | AU10: CLIA_CMS_FDA_baseline; state_variation_not_fully_coded | AV10: 0 | AW10: 0 | AX10: 0 | AY10: =BU10 -> 34 | AZ10: 27 | BA10: 12743 | BB10: 23372215 | BC10: FFM | BD10: republican_trifecta | BE10: restrictive | BF10: HB 677 (2025) | BG10: https://www.flsenate.gov/Session/Bill/2025/677 | BH10: https://triagecancer.org/state-laws/health-insurance-fertility-services; https://surrogacy360.org/wp-content/uploads/2024/08/Regulation-Details-in-the-US-by-State_8.6.24.pdf; https://www.asrm.org/advocacy-and-policy/reproductive-rights/summary-reports/state-abortion-laws-potential-implications-for-reproductive-medicine/; https://www.guttmacher.org/2025/12/state-policy-trends-2025-full-year-analysis; https://www.cdc.gov/art/php/nass/index.html; https://www.cdc.gov/art/success-rates/index.html; https://www.cms.gov/medicare/quality/clinical-laboratory-improvement-amendments; https://www.cms.gov/marketplace/in-person-assisters/training-webinars/training/marketplaces-map; https://ballotpedia.org/State_government_trifectas; https://www.britannica.com/topic/largest-U-S-state-by-population; https://www.guttmacher.org/united-states/abortion | BI10: State group health insurance must cover fertility retrieval/preservation for cancer-related iatrogenic infertility effective 2026-01-01. Surrogacy fields coded from Surrogacy360 2024 state-by-state summary; interpret as starter classification requiring legal review for publication. Eligibility/LGBTQ fields on this row were filled as a 2026 starter classification based on absence of a statewide IVF-treatment mandate or unclear scope in the source used; this should not be interpreted as a full review of all private plans or clinic access in the state. Embryo/personhood/disposition fields were filled conservatively in this pass. Unless a state had a clear embryo-specific rule in the secondary sources used, values were set to not_identified_in_secondary_sources_used rather than treated as definitive absence of law. Clinic/reporting fields in this pass were coded from federal baselines: CDC NASS/FCSRCA reporting and CMS CLIA materials; insurance marketplace type from CMS Plan Year 2026 marketplace map; political control from Ballotpedia current trifecta status; population uses 2024 state estimate table summarized by Britannica from U.S. Census data. IVF clinic counts and cycle counts remain blank pending direct state-level CDC extraction. | BJ10: RRM | BK10: partially_filled_needs_primary_law_review | BL10: =IFERROR((AZ10/BB10)*1000000,0) -> 1.1552179 | BM10: =IFERROR((BA10/BB10)*1000000,0) -> 545.22004 | BN10: =IFERROR(VLOOKUP(H10,index_logic!$A$4:$B$8,2,FALSE),0) -> 4 | BO10: =IFERROR(VLOOKUP(AD10,index_logic!$D$4:$E$21,2,FALSE),0) -> 3 | BP10: =IFERROR(VLOOKUP(AM10,index_logic!$G$4:$H$6,2,FALSE),0) -> 3 | BQ10: =IFERROR(VLOOKUP(AH10,index_logic!$J$4:$K$6,2,FALSE),0) -> 15 | BR10: =IFERROR(VLOOKUP(BE10,index_logic!$M$4:$N$7,2,FALSE),0) -> 3 | BS10: =IFERROR(VLOOKUP(BL10,index_logic!$P$4:$Q$9,2,TRUE),0) -> 4 | BT10: =IFERROR(VLOOKUP(BM10,index_logic!$S$4:$T$9,2,TRUE),0) -> 2 | BU10: =BN10+BO10+BP10+BQ10+BR10+BS10+BT10 -> 34 | BV10: =IF(BU10>=80,"Very High",IF(BU10>=65,"High",IF(BU10>=50,"Moderate",IF(BU10>=35,"Low","Very Low")))) -> Very Low
A11: Georgia | B11: GA | C11: 2026 | D11: current_snapshot | E11: 0 | F11: NA | G11: 2026-03-12 | H11: none_identified | I11: No statewide infertility/IVF coverage mandate identified in source used | J11: no_statewide_ivf_mandate_identified | K11: 0 | L11: 0 | M11: 0 | N11: 0 | O11: not identified | P11: 0 | Q11: 0 | R11: 0 | U11: none_identified | V11: 0 | X11: no_statewide_ivf_treatment_eligibility_rule_identified | Y11: no_statewide_ivf_treatment_eligibility_rule_identified | Z11: no_statewide_ivf_treatment_eligibility_rule_identified | AA11: not_applicable_no_statewide_ivf_treatment_mandate | AB11: not_applicable_no_statewide_ivf_treatment_mandate | AC11: none stated in source used | AD11: no_statewide_ivf_treatment_eligibility_rule_identified | AE11: no_statewide_ivf_treatment_eligibility_rule_identified | AF11: no_statewide_ivf_treatment_eligibility_rule_identified | AG11: no_statewide_ivf_treatment_eligibility_rule_identified | AH11: not_identified_in_secondary_sources_used | AI11: not_identified_in_secondary_sources_used | AJ11: not_identified_in_secondary_sources_used | AK11: not_identified_in_secondary_sources_used | AL11: not_identified_in_secondary_sources_used | AM11: restricted | AN11: unclear | AO11: no_or_unclear | AP11: unclear | AQ11: adoption or post-birth process often required | AR11: no_fertility_specific_state_clinic_license_coded_in_this_pass | AS11: federal_CDC_NASS_reporting_baseline | AT11: federal_FCSRCA_CDC_public_reporting | AU11: CLIA_CMS_FDA_baseline; state_variation_not_fully_coded | AV11: 0 | AW11: 0 | AX11: 0 | AY11: =BU11 -> 31 | AZ11: 17 | BA11: 7664 | BB11: 11180878 | BC11: SBM | BD11: republican_trifecta | BE11: restrictive | BF11: No statewide infertility/IVF mandate identified in Triage Cancer state-law chart | BG11: https://triagecancer.org/state-laws/health-insurance-fertility-services | BH11: https://triagecancer.org/state-laws/health-insurance-fertility-services; https://surrogacy360.org/wp-content/uploads/2024/08/Regulation-Details-in-the-US-by-State_8.6.24.pdf; https://www.asrm.org/advocacy-and-policy/reproductive-rights/summary-reports/state-abortion-laws-potential-implications-for-reproductive-medicine/; https://www.guttmacher.org/2025/12/state-policy-trends-2025-full-year-analysis; https://www.cdc.gov/art/php/nass/index.html; https://www.cdc.gov/art/success-rates/index.html; https://www.cms.gov/medicare/quality/clinical-laboratory-improvement-amendments; https://www.cms.gov/marketplace/in-person-assisters/training-webinars/training/marketplaces-map; https://ballotpedia.org/State_government_trifectas; https://www.britannica.com/topic/largest-U-S-state-by-population; https://www.guttmacher.org/united-states/abortion | BI11: Starter row only. Needs primary-law verification for Medicaid, public funding, eligibility, embryo rules, surrogacy, clinic regulation, and utilization variables. Surrogacy fields coded from Surrogacy360 2024 state-by-state summary; interpret as starter classification requiring legal review for publication. Eligibility/LGBTQ fields on this row were filled as a 2026 starter classification based on absence of a statewide IVF-treatment mandate or unclear scope in the source used; this should not be interpreted as a full review of all private plans or clinic access in the state. Embryo/personhood/disposition fields were filled conservatively in this pass. Unless a state had a clear embryo-specific rule in the secondary sources used, values were set to not_identified_in_secondary_sources_used rather than treated as definitive absence of law. Clinic/reporting fields in this pass were coded from federal baselines: CDC NASS/FCSRCA reporting and CMS CLIA materials; insurance marketplace type from CMS Plan Year 2026 marketplace map; political control from Ballotpedia current trifecta status; population uses 2024 state estimate table summarized by Britannica from U.S. Census data. IVF clinic counts and cycle counts remain blank pending direct state-level CDC extraction. | BJ11: RRM | BK11: partially_filled_needs_primary_law_review | BL11: =IFERROR((AZ11/BB11)*1000000,0) -> 1.520453 | BM11: =IFERROR((BA11/BB11)*1000000,0) -> 685.45601 | BN11: =IFERROR(VLOOKUP(H11,index_logic!$A$4:$B$8,2,FALSE),0) -> 0 | BO11: =IFERROR(VLOOKUP(AD11,index_logic!$D$4:$E$21,2,FALSE),0) -> 3 | BP11: =IFERROR(VLOOKUP(AM11,index_logic!$G$4:$H$6,2,FALSE),0) -> 3 | BQ11: =IFERROR(VLOOKUP(AH11,index_logic!$J$4:$K$6,2,FALSE),0) -> 15 | BR11: =IFERROR(VLOOKUP(BE11,index_logic!$M$4:$N$7,2,FALSE),0) -> 3 | BS11: =IFERROR(VLOOKUP(BL11,index_logic!$P$4:$Q$9,2,TRUE),0) -> 5 | BT11: =IFERROR(VLOOKUP(BM11,index_logic!$S$4:$T$9,2,TRUE),0) -> 2 | BU11: =BN11+BO11+BP11+BQ11+BR11+BS11+BT11 -> 31 | BV11: =IF(BU11>=80,"Very High",IF(BU11>=65,"High",IF(BU11>=50,"Moderate",IF(BU11>=35,"Low","Very Low")))) -> Very Low
A12: Hawaii | B12: HI | C12: 2026 | D12: active | E12: 1989 | F12: NA | G12: 2026-03-12 | H12: cover | I12: One-time outpatient IVF benefit where eligibility is met | J12: IVF-specific, one-time benefit | K12: 1 outpatient IVF benefit | L12: one-time benefit | M12: not specified | N12: not specified | O12: not identified | P12: no; source says own eggs and spouse sperm | Q12: not specified | R12: not identified | S12: not identified | T12: not identified | U12: none_identified | V12: 0 | W12: not identified | X12: married_spousal_gametes_required | Y12: 5-year infertility history or specified medical conditions | Z12: must first fail other applicable covered infertility treatments | AA12: not specified in source used | AB12: not specified in source used | AC12: none stated in source used | AD12: restricted_current_statute uses spouse requirement | AE12: excluded_current_statute uses spouse requirement | AF12: not explicitly addressed; current statute uses spouse/sex-specific framing | AG12: patient oocytes must be fertilized with spouse sperm | AH12: not_identified_in_secondary_sources_used | AI12: not_identified_in_secondary_sources_used | AJ12: not_identified_in_secondary_sources_used | AK12: not_identified_in_secondary_sources_used | AL12: not_identified_in_secondary_sources_used | AM12: restricted | AN12: unclear | AO12: no_or_unclear | AP12: unclear | AQ12: adoption or post-birth process often required | AR12: no_fertility_specific_state_clinic_license_coded_in_this_pass | AS12: federal_CDC_NASS_reporting_baseline | AT12: federal_FCSRCA_CDC_public_reporting | AU12: CLIA_CMS_FDA_baseline; state_variation_not_fully_coded | AV12: 1989 | AW12: 2024 | AX12: 0 | AY12: =BU12 -> 65 | AZ12: 3 | BA12: 992 | BB12: 1446146 | BC12: FFM | BD12: democratic_trifecta | BE12: supportive_or_protective | BF12: HI Rev Stat § 431:10A-116.5 | BG12: https://law.justia.com/codes/hawaii/title-24/chapter-431/section-431-10a-116-5/ | BH12: https://triagecancer.org/state-laws/health-insurance-fertility-services; https://surrogacy360.org/wp-content/uploads/2024/08/Regulation-Details-in-the-US-by-State_8.6.24.pdf; https://www.reproductivefacts.org/patient-advocacy/state-and-territory-infertility-insurance-laws/hawaii/; https://law.justia.com/codes/hawaii/title-24/chapter-431/section-431-10a-116-5/; https://www.asrm.org/advocacy-and-policy/reproductive-rights/summary-reports/state-abortion-laws-potential-implications-for-reproductive-medicine/; https://www.guttmacher.org/2025/12/state-policy-trends-2025-full-year-analysis; https://www.cdc.gov/art/php/nass/index.html; https://www.cdc.gov/art/success-rates/index.html; https://www.cms.gov/medicare/quality/clinical-laboratory-improvement-amendments; https://www.cms.gov/marketplace/in-person-assisters/training-webinars/training/marketplaces-map; https://ballotpedia.org/State_government_trifectas; https://www.britannica.com/topic/largest-U-S-state-by-population; https://www.guttmacher.org/united-states/abortion | BI12: Source also notes 5 years infertility or certain medical conditions as eligibility routes. Surrogacy fields coded from Surrogacy360 2024 state-by-state summary; interpret as starter classification requiring legal review for publication. Eligibility/LGBTQ fields updated in this pass using current 2026 state-law summaries and/or statute text where available; some entries remain conservative where the source did not clearly resolve LGBTQ or gender-identity treatment eligibility. Embryo/personhood/disposition fields were filled conservatively in this pass. Unless a state had a clear embryo-specific rule in the secondary sources used, values were set to not_identified_in_secondary_sources_used rather than treated as definitive absence of law. Clinic/reporting fields in this pass were coded from federal baselines: CDC NASS/FCSRCA reporting and CMS CLIA materials; insurance marketplace type from CMS Plan Year 2026 marketplace map; political control from Ballotpedia current trifecta status; population uses 2024 state estimate table summarized by Britannica from U.S. Census data. IVF clinic counts and cycle counts remain blank pending direct state-level CDC extraction. | BJ12: RRM | BK12: partially_filled_needs_primary_law_review | BL12: =IFERROR((AZ12/BB12)*1000000,0) -> 2.0744793 | BM12: =IFERROR((BA12/BB12)*1000000,0) -> 685.96117 | BN12: =IFERROR(VLOOKUP(H12,index_logic!$A$4:$B$8,2,FALSE),0) -> 30 | BO12: =IFERROR(VLOOKUP(AD12,index_logic!$D$4:$E$21,2,FALSE),0) -> 0 | BP12: =IFERROR(VLOOKUP(AM12,index_logic!$G$4:$H$6,2,FALSE),0) -> 3 | BQ12: =IFERROR(VLOOKUP(AH12,index_logic!$J$4:$K$6,2,FALSE),0) -> 15 | BR12: =IFERROR(VLOOKUP(BE12,index_logic!$M$4:$N$7,2,FALSE),0) -> 10 | BS12: =IFERROR(VLOOKUP(BL12,index_logic!$P$4:$Q$9,2,TRUE),0) -> 5 | BT12: =IFERROR(VLOOKUP(BM12,index_logic!$S$4:$T$9,2,TRUE),0) -> 2 | BU12: =BN12+BO12+BP12+BQ12+BR12+BS12+BT12 -> 65 | BV12: =IF(BU12>=80,"Very High",IF(BU12>=65,"High",IF(BU12>=50,"Moderate",IF(BU12>=35,"Low","Very Low")))) -> High
